<?xml version="1.0"?>
<robot name="altair_hexacopter">

  <!-- Base Link (Body) -->
  <link name="base_link">
    <inertial>
      <mass value="2.0"/> <!-- 2.0 kg estimate -->
      <origin rpy="0 0 0" xyz="0 0 0"/>
      <inertia ixx="0.05" ixy="0" ixz="0" iyy="0.05" iyz="0" izz="0.1"/>
    </inertial>
    <visual>
      <geometry>
        <cylinder length="0.05" radius="0.15"/>
      </geometry>
      <material name="grey">
        <color rgba="0.5 0.5 0.5 1"/>
      </material>
    </visual>
    <collision>
      <geometry>
        <cylinder length="0.05" radius="0.15"/>
      </geometry>
    </collision>
  </link>

  <!-- Macro for Arm with Tilt Mechanism -->
  <!-- 
       id: Arm ID (1-6)
       angle: Arm angle in radians
       x, y: Position of arm base
  -->
  
  <!-- Arm 1 (0 deg) -->
  <link name="arm_1">
    <visual>
        <geometry><box size="0.25 0.02 0.02"/></geometry>
        <origin xyz="0.125 0 0"/>
        <material name="black"><color rgba="0 0 0 1"/></material>
    </visual>
  </link>
  <joint name="arm_1_joint" type="fixed">
    <parent link="base_link"/>
    <child link="arm_1"/>
    <origin rpy="0 0 0" xyz="0 0 0"/>
  </joint>

  <!-- Tilt Servo 1 -->
  <link name="tilt_1_link">
     <visual>
        <geometry><cylinder length="0.04" radius="0.02"/></geometry>
        <origin rpy="1.5708 0 0" xyz="0 0 0"/> <!-- Horizontal Servo -->
        <material name="blue"><color rgba="0 0 1 1"/></material>
     </visual>
  </link>
  <joint name="tilt_1_joint" type="revolute">
    <parent link="arm_1"/>
    <child link="tilt_1_link"/>
    <origin rpy="0 0 0" xyz="0.25 0 0"/>
    <axis xyz="1 0 0"/> <!-- Tilts around arm axis -->
    <limit lower="-1.57" upper="1.57" effort="5.0" velocity="5.0"/>
  </joint>

  <!-- Motor 1 -->
  <link name="rotor_1">
    <visual>
        <geometry><cylinder length="0.01" radius="0.1"/></geometry>
        <material name="red"><color rgba="1 0 0 1"/></material>
    </visual>
  </link>
  <joint name="rotor_1_joint" type="continuous">
    <parent link="tilt_1_link"/>
    <child link="rotor_1"/>
    <origin rpy="0 0 0" xyz="0 0 0.03"/>
    <axis xyz="0 0 1"/>
  </joint>

  <!-- Arm 2 (60 deg) -->
  <link name="arm_2">
    <visual>
        <geometry><box size="0.25 0.02 0.02"/></geometry>
        <origin xyz="0.125 0 0"/>
        <material name="black"/>
    </visual>
  </link>
  <joint name="arm_2_joint" type="fixed">
    <parent link="base_link"/>
    <child link="arm_2"/>
    <origin rpy="0 0 1.0472" xyz="0 0 0"/>
  </joint>
  <link name="tilt_2_link">
     <visual>
        <geometry><cylinder length="0.04" radius="0.02"/></geometry>
        <origin rpy="1.5708 0 0" xyz="0 0 0"/>
        <material name="blue"/>
     </visual>
  </link>
  <joint name="tilt_2_joint" type="revolute">
    <parent link="arm_2"/>
    <child link="tilt_2_link"/>
    <origin rpy="0 0 0" xyz="0.25 0 0"/>
    <axis xyz="1 0 0"/>
    <limit lower="-1.57" upper="1.57" effort="5.0" velocity="5.0"/>
  </joint>
  <link name="rotor_2">
    <visual>
        <geometry><cylinder length="0.01" radius="0.1"/></geometry>
        <material name="white"><color rgba="1 1 1 1"/></material>
    </visual>
  </link>
  <joint name="rotor_2_joint" type="continuous">
    <parent link="tilt_2_link"/>
    <child link="rotor_2"/>
    <origin rpy="0 0 0" xyz="0 0 0.03"/>
    <axis xyz="0 0 1"/>
  </joint>

  <!-- Arm 3 (120 deg) -->
  <link name="arm_3">
    <visual>
        <geometry><box size="0.25 0.02 0.02"/></geometry>
        <origin xyz="0.125 0 0"/>
        <material name="black"/>
    </visual>
  </link>
  <joint name="arm_3_joint" type="fixed">
    <parent link="base_link"/>
    <child link="arm_3"/>
    <origin rpy="0 0 2.0944" xyz="0 0 0"/>
  </joint>
  <link name="tilt_3_link">
     <visual>
        <geometry><cylinder length="0.04" radius="0.02"/></geometry>
        <origin rpy="1.5708 0 0" xyz="0 0 0"/>
        <material name="blue"/>
     </visual>
  </link>
  <joint name="tilt_3_joint" type="revolute">
    <parent link="arm_3"/>
    <child link="tilt_3_link"/>
    <origin rpy="0 0 0" xyz="0.25 0 0"/>
    <axis xyz="1 0 0"/>
    <limit lower="-1.57" upper="1.57" effort="5.0" velocity="5.0"/>
  </joint>
  <link name="rotor_3">
    <visual>
        <geometry><cylinder length="0.01" radius="0.1"/></geometry>
        <material name="white"/>
    </visual>
  </link>
  <joint name="rotor_3_joint" type="continuous">
    <parent link="tilt_3_link"/>
    <child link="rotor_3"/>
    <origin rpy="0 0 0" xyz="0 0 0.03"/>
    <axis xyz="0 0 1"/>
  </joint>

  <!-- Arm 4 (180 deg) -->
  <link name="arm_4">
    <visual>
        <geometry><box size="0.25 0.02 0.02"/></geometry>
        <origin xyz="0.125 0 0"/>
        <material name="black"/>
    </visual>
  </link>
  <joint name="arm_4_joint" type="fixed">
    <parent link="base_link"/>
    <child link="arm_4"/>
    <origin rpy="0 0 3.14159" xyz="0 0 0"/>
  </joint>
  <link name="tilt_4_link">
     <visual>
        <geometry><cylinder length="0.04" radius="0.02"/></geometry>
        <origin rpy="1.5708 0 0" xyz="0 0 0"/>
        <material name="blue"/>
     </visual>
  </link>
  <joint name="tilt_4_joint" type="revolute">
    <parent link="arm_4"/>
    <child link="tilt_4_link"/>
    <origin rpy="0 0 0" xyz="0.25 0 0"/>
    <axis xyz="1 0 0"/>
    <limit lower="-1.57" upper="1.57" effort="5.0" velocity="5.0"/>
  </joint>
  <link name="rotor_4">
    <visual>
        <geometry><cylinder length="0.01" radius="0.1"/></geometry>
        <material name="red"/>
    </visual>
  </link>
  <joint name="rotor_4_joint" type="continuous">
    <parent link="tilt_4_link"/>
    <child link="rotor_4"/>
    <origin rpy="0 0 0" xyz="0 0 0.03"/>
    <axis xyz="0 0 1"/>
  </joint>

  <!-- Arm 5 (240 deg) -->
  <link name="arm_5">
    <visual>
        <geometry><box size="0.25 0.02 0.02"/></geometry>
        <origin xyz="0.125 0 0"/>
        <material name="black"/>
    </visual>
  </link>
  <joint name="arm_5_joint" type="fixed">
    <parent link="base_link"/>
    <child link="arm_5"/>
    <origin rpy="0 0 4.1888" xyz="0 0 0"/>
  </joint>
  <link name="tilt_5_link">
     <visual>
        <geometry><cylinder length="0.04" radius="0.02"/></geometry>
        <origin rpy="1.5708 0 0" xyz="0 0 0"/>
        <material name="blue"/>
     </visual>
  </link>
  <joint name="tilt_5_joint" type="revolute">
    <parent link="arm_5"/>
    <child link="tilt_5_link"/>
    <origin rpy="0 0 0" xyz="0.25 0 0"/>
    <axis xyz="1 0 0"/>
    <limit lower="-1.57" upper="1.57" effort="5.0" velocity="5.0"/>
  </joint>
  <link name="rotor_5">
    <visual>
        <geometry><cylinder length="0.01" radius="0.1"/></geometry>
        <material name="white"/>
    </visual>
  </link>
  <joint name="rotor_5_joint" type="continuous">
    <parent link="tilt_5_link"/>
    <child link="rotor_5"/>
    <origin rpy="0 0 0" xyz="0 0 0.03"/>
    <axis xyz="0 0 1"/>
  </joint>

  <!-- Arm 6 (300 deg) -->
  <link name="arm_6">
    <visual>
        <geometry><box size="0.25 0.02 0.02"/></geometry>
        <origin xyz="0.125 0 0"/>
        <material name="black"/>
    </visual>
  </link>
  <joint name="arm_6_joint" type="fixed">
    <parent link="base_link"/>
    <child link="arm_6"/>
    <origin rpy="0 0 5.2360" xyz="0 0 0"/>
  </joint>
  <link name="tilt_6_link">
     <visual>
        <geometry><cylinder length="0.04" radius="0.02"/></geometry>
        <origin rpy="1.5708 0 0" xyz="0 0 0"/>
        <material name="blue"/>
     </visual>
  </link>
  <joint name="tilt_6_joint" type="revolute">
    <parent link="arm_6"/>
    <child link="tilt_6_link"/>
    <origin rpy="0 0 0" xyz="0.25 0 0"/>
    <axis xyz="1 0 0"/>
    <limit lower="-1.57" upper="1.57" effort="5.0" velocity="5.0"/>
  </joint>
  <link name="rotor_6">
    <visual>
        <geometry><cylinder length="0.01" radius="0.1"/></geometry>
        <material name="white"/>
    </visual>
  </link>
  <joint name="rotor_6_joint" type="continuous">
    <parent link="tilt_6_link"/>
    <child link="rotor_6"/>
    <origin rpy="0 0 0" xyz="0 0 0.03"/>
    <axis xyz="0 0 1"/>
  </joint>

</robot>
